<?xml version="1.0" ?>
<robot name="robot" xmlns:xacro="http://ros.org/wiki/xacro">

  <material name="black">
      <color rgba="0.0 0.0 0.0 1.0"/>
  </material>

  <material name="dark">
    <color rgba="0.3 0.3 0.3 1.0"/>
  </material>

  <material name="light_black">
    <color rgba="0.4 0.4 0.4 1.0"/>
  </material>

  <material name="blue">
    <color rgba="0.0 0.0 0.8 1.0"/>
  </material>

  <material name="green">
    <color rgba="0.0 0.8 0.0 1.0"/>
  </material>

  <material name="grey">
    <color rgba="0.5 0.5 0.5 1.0"/>
  </material>

  <material name="orange">
    <color rgba="1.0 0.42 0.04 1.0"/>
  </material>

  <material name="brown">
    <color rgba="1.0 0.81 0.76 1.0"/>
  </material>

  <material name="red">
    <color rgba="0.8 0.0 0.0 1.0"/>
  </material>

  <material name="white">
    <color rgba="1.0 1.0 1.0 1.0"/>
  </material>


  <!-- BASE FOOTPRINT -->
  <link name="base_footprint"/>

  <!-- BASE LINK -->
  <link name="base_link">
    <visual>
      <origin xyz="0.0 0.0 0.0" rpy="0 0 0"/>
      <geometry>
        <box size="0.4 0.21 0.05"/>
      </geometry>
      <material name="light_black"/>
    </visual>

    <collision>
      <origin xyz="0.0 0.0 0.0" rpy="0 0 0"/>
      <geometry>
        <box size="0.4 0.21 0.05"/>
      </geometry>
    </collision>

    <inertial>
      <origin xyz="0 0 0" rpy="0 0 0"/>
      <mass value="1"/>
      <inertia ixx="6.6666667e-03" ixy="0" ixz="0"
               iyy="6.6666667e-03" iyz="0"
               izz="6.6666667e-03" />
    </inertial>
  </link>

  <joint name="base_joint" type="fixed">
    <parent link="base_footprint"/>
    <child link="base_link"/>
    <origin xyz="0.0 0.0 0.2" rpy="0 0 0"/>
  </joint>

  <gazebo reference="base_link">
    <material>Gazebo/DarkGrey</material>
  </gazebo>


  <!-- WHEEL LEFT Front -->
  <link name="wheel_lf">
    <visual>
      <origin xyz="0 0 0" rpy="0 0 0"/>
      <geometry>
        <cylinder length="0.055" radius="0.123345"/>
      </geometry>
      <material name="dark"/>
    </visual>

    <collision>
      <origin xyz="0 0 0" rpy="0 0 0"/>
      <geometry>
        <cylinder length="0.055" radius="0.123345"/>
      </geometry>
    </collision>

    <inertial>
      <origin xyz="0 0 0" />
      <mass value="3" />
      <inertia ixx="4.0675e-02" ixy="0" ixz="0"
               iyy="4.0675e-02" iyz="0"
               izz="8e-02" />
    </inertial>
  </link>

  <joint name="wheel_lf_joint" type="continuous">
    <parent link="base_link"/>
    <child link="wheel_lf"/>
    <origin xyz="0.1685 0.155 -0.035" rpy="-1.57079632679 0 0"/>
    <axis xyz="0 0 1"/>
  </joint>

  <gazebo reference="wheel_lf">
    <!--<mu1>20.0</mu1>
    <mu2>20.0</mu2>-->
    <!--<kp>100000000.0</kp>
    <kd>10000.0</kd>-->
    <!--<minDepth>0.001</minDepth>-->
    <material>Gazebo/FlatBlack</material>
    <selfCollide>false</selfCollide>
    <mu1 value="0.5"/>
    <mu2 value="0.5"/>
    <kp value="10000000.0" />
    <kd value="1" />
    <fdir1 value="1 0 0"/>
  </gazebo>

<!-- WHEEL LEFT BACK -->
  <link name="wheel_lb">
    <visual>
      <origin xyz="0 0 0" rpy="0 0 0"/>
      <geometry>
        <cylinder length="0.06" radius="0.123345"/>
      </geometry>
      <material name="dark"/>
    </visual>

    <collision>
      <origin xyz="0 0 0" rpy="0 0 0"/>
      <geometry>
        <cylinder length="0.06" radius="0.123345"/>
      </geometry>
    </collision>

    <inertial>
      <origin xyz="0 0 0" />
      <mass value="3" />
      <inertia ixx="4.0675e-02" ixy="0" ixz="0"
               iyy="4.0675e-02" iyz="0"
               izz="8e-02" />
    </inertial>
  </link>

  <joint name="wheel_lb_joint" type="continuous">
    <parent link="base_link"/>
    <child link="wheel_lb"/>
    <origin xyz="-0.1685 0.16 -0.035" rpy="-1.57079632679 0 0"/>
    <axis xyz="0 0 1"/>
  </joint>

  <gazebo reference="wheel_lb">
    <!--<mu1>20.0</mu1>
    <mu2>20.0</mu2>-->
    <!--<kp>100000000.0</kp>
    <kd>10000.0</kd>-->
    <!--<minDepth>0.001</minDepth>-->
    <material>Gazebo/FlatBlack</material>
    <selfCollide>false</selfCollide>
    <mu1 value="0.5"/>
    <mu2 value="0.5"/>
    <kp value="10000000.0" />
    <kd value="1" />
    <fdir1 value="1 0 0"/>
  </gazebo>


  <!-- WHEEL RIGHT-->
  <link name="wheel_rf">
    <visual>
      <origin xyz="0 0 0" rpy="0.0 0 0"/>
      <geometry>
        <cylinder length="0.055" radius="0.123345"/>
      </geometry>
      <material name="dark"/>
    </visual>

    <collision>
      <origin xyz="0 0 0" rpy="0 0 0"/>
      <geometry>
        <cylinder length="0.055" radius="0.123345"/>
      </geometry>
    </collision>

    <inertial>
      <origin xyz="0 0 0" />
      <mass value="3" />
      <inertia ixx="4.0675e-02" ixy="0" ixz="0"
               iyy="4.0675e-02" iyz="0"
               izz="8e-02" />
      </inertial>
  </link>

  <joint name="wheel_rf_joint" type="continuous"> <!-- continuous-->
    <parent link="base_link"/>
    <child link="wheel_rf"/>
    <origin xyz="0.1685 -0.155 -0.035" rpy="-1.57079632679 0 0"/>
    <axis xyz="0 0 1"/>
  </joint>

  <gazebo reference="wheel_rf">
    <!--<mu1>20.0</mu1>
    <mu2>20.0</mu2>-->
    <!--<kp>100000000.0</kp>
    <kd>10000.0</kd>-->
    <!--<minDepth>0.001</minDepth>-->
    <material>Gazebo/FlatBlack</material>
    <selfCollide>false</selfCollide>
    <mu1 value="0.5"/>
    <mu2 value="0.5"/>
    <kp value="10000000.0" />
    <kd value="1" />
    <fdir1 value="1 0 0"/>
  </gazebo>

  <!-- WHEEL RIGHT Back-->
  <link name="wheel_rb">
    <visual>
      <origin xyz="0 0 0" rpy="0.0 0 0"/>
      <geometry>
        <cylinder length="0.06" radius="0.123345"/>
      </geometry>
      <material name="dark"/>
    </visual>

    <collision>
      <origin xyz="0 0 0" rpy="0.0 0 0"/>
      <geometry>
        <cylinder length="0.06" radius="0.123345"/>
      </geometry>
    </collision>

    <inertial>
      <origin xyz="0 0 0" />
      <mass value="3" />
      <inertia ixx="4.0675e-02" ixy="0" ixz="0"
               iyy="4.0675e-02" iyz="0"
               izz="8e-02" />
      </inertial>
  </link>

  <joint name="wheel_rb_joint" type="continuous"> <!-- continuous-->
    <parent link="base_link"/>
    <child link="wheel_rb"/>
    <origin xyz="-0.1685 -0.16 -0.035" rpy="-1.57079632679 0 0"/>
    <axis xyz="0 0 1"/>
  </joint>

  <gazebo reference="wheel_rb">
    <!--<mu1>20.0</mu1>
    <mu2>20.0</mu2>-->
    <!--<kp>100000000.0</kp>
    <kd>10000.0</kd>-->
    <!--<minDepth>0.001</minDepth>-->
    <material>Gazebo/FlatBlack</material>
    <selfCollide>false</selfCollide>
    <mu1 value="0.5"/>
    <mu2 value="0.5"/>
    <kp value="10000000.0" />
    <kd value="1" />
    <fdir1 value="1 0 0"/>
  </gazebo>


  <!-- CAMERA FRONT -->
  <link name="camera_front_link">
    <visual>
      <origin xyz="0 0 0" rpy="0.0 0 0"/>
      <geometry>
        <box size="0.005 0.1 0.02"/>
      </geometry>
      <material name="blue"/>
    </visual>

    <collision>
      <origin xyz="0 0 0" rpy="0 0 0"/>
      <geometry>
        <box size="0.005 0.1 0.02"/>
      </geometry>
    </collision>

    <inertial>
      <origin xyz="0 0 0" />
      <mass value="1" />
      <inertia ixx="0.0" ixy="0.0" ixz="0.0"
               iyy="0.0" iyz="0.0"
               izz="0.0" />
    </inertial>
  </link>

  <joint name="camera_front_joint" type="fixed">
    <parent link="base_link"/>
    <child link="camera_front_link"/>
    <origin xyz="0.35 0.0 0.1" rpy="-2.35619449 0 -1.57079632679"/>
    <!--X Plus-->
  </joint>

  <link name="camera_front_virtual_link">
  </link>
  <joint name="camera_front_virtual_joint" type="fixed">
    <parent link="camera_front_link"/>
    <child link="camera_front_virtual_link"/>
    <origin xyz="0 0 0" rpy="1.57079632679 -1.57079632679 0"/> <!-- 1.57079632679 1.57079632679"/> -->
  </joint>

  <!-- CAMERA Back -->
  <link name="camera_back_link">
    <visual>
      <origin xyz="0 0 0" rpy="0.0 0 0"/>
      <geometry>
        <box size="0.005 0.1 0.02"/>
      </geometry>
      <material name="blue"/>
    </visual>

    <collision>
      <origin xyz="0 0 0" rpy="0 0 0"/>
      <geometry>
        <box size="0.005 0.1 0.02"/>
      </geometry>
    </collision>

    <inertial>
      <origin xyz="0 0 0" />
      <mass value="1" />
      <inertia ixx="0.0" ixy="0.0" ixz="0.0"
               iyy="0.0" iyz="0.0"
               izz="0.0" />
    </inertial>
  </link>

  <joint name="camera_back_joint" type="fixed">
    <parent link="base_link"/>
    <child link="camera_back_link"/>
    <origin xyz="-0.35 0.0 0.1" rpy="-2.35619449 0 1.57079632679"/>
  </joint>

  <link name="camera_back_virtual_link">
  </link>
  <joint name="camera_back_virtual_joint" type="fixed">
    <parent link="camera_back_link"/>
    <child link="camera_back_virtual_link"/>
    <origin xyz="0 0 0" rpy="1.57079632679 -1.57079632679 0"/>
  </joint>

  <!-- CAMERA LEFT -->
  <link name="camera_left_link">
    <visual>
      <origin xyz="0 0 0" rpy="0.0 0 0"/>
      <geometry>
        <box size="0.005 0.1 0.02"/>
      </geometry>
      <material name="blue"/>
    </visual>

    <collision>
      <origin xyz="0 0 0" rpy="0 0 0"/>
      <geometry>
        <box size="0.005 0.1 0.02"/>
      </geometry>
    </collision>

    <inertial>
      <origin xyz="0 0 0" />
      <mass value="1" />
      <inertia ixx="0.0" ixy="0.0" ixz="0.0"
               iyy="0.0" iyz="0.0"
               izz="0.0" />
    </inertial>
  </link>

  <joint name="camera_left_joint" type="fixed">
    <parent link="base_link"/>
    <child link="camera_left_link"/>
    <origin xyz="0.0 0.25 0.1" rpy="-2.35619449 0 0"/>
  </joint>

  <link name="camera_left_virtual_link">
  </link>
  <joint name="camera_left_virtual_joint" type="fixed">
    <parent link="camera_left_link"/>
    <child link="camera_left_virtual_link"/>
    <origin xyz="0 0 0" rpy="1.57079632679 -1.57079632679 0"/>
  </joint>


  <!-- CAMERA RIGHT -->
  <link name="camera_right_link">
    <visual>
      <origin xyz="0 0 0" rpy="0.0 0 0"/>
      <geometry>
        <box size="0.005 0.1 0.02"/>
      </geometry>
      <material name="blue"/>
    </visual>

    <collision>
      <origin xyz="0 0 0" rpy="0 0 0"/>
      <geometry>
        <box size="0.005 0.1 0.02"/>
      </geometry>
    </collision>

    <inertial>
      <origin xyz="0 0 0" />
      <mass value="1" />
      <inertia ixx="0.0" ixy="0.0" ixz="0.0"
               iyy="0.0" iyz="0.0"
               izz="0.0" />
    </inertial>
  </link>

  <joint name="camera_right_joint" type="fixed">
    <parent link="base_link"/>
    <child link="camera_right_link"/>
    <origin xyz="0.0 -0.25 0.1" rpy="-2.35619449 0 3.1415926536"/>
  </joint>

  <link name="camera_right_virtual_link">
  </link>
  <joint name="camera_right_virtual_joint" type="fixed">
    <parent link="camera_right_link"/>
    <child link="camera_right_virtual_link"/>
    <origin xyz="0 0 0" rpy="1.57079632679 -1.57079632679 0"/>
  </joint>

  <!-- IMU -->
  <link name="imu_link">
    <visual>
      <origin xyz="0 0 0" rpy="0.0 0 0"/>
      <geometry>
        <box size="0.05 0.05 0.05"/>
      </geometry>
      <material name="blue"/>
    </visual>

    <collision>
      <origin xyz="0 0 0" rpy="0 0 0"/>
      <geometry>
        <box size="0.05 0.05 0.05"/>
      </geometry>
    </collision>

    <inertial>
      <origin xyz="0 0 0" />
      <mass value="0" />
      <inertia ixx="0.0" ixy="0.0" ixz="0.0"
               iyy="0.0" iyz="0.0"
               izz="0.0" />
    </inertial>
  </link>

  <joint name="imu_join" type="fixed">
    <parent link="base_link"/>
    <child link="imu_link"/>
    <origin xyz="0 0 0.1" rpy="0 0 0"/>
  </joint>



  <!--

    !!!!!
    GAZEBO SECTION
    !!!!!

  -->


  <!-- JOINT STATES -->
  <gazebo>

    <plugin name="gazebo_ros_joint_state_publisher" filename="libgazebo_ros_joint_state_publisher.so">
      <robotNamespace>robot</robotNamespace>
      <topicName>joint_states</topicName>
      <!--<argument>joint_states:=joint_states</argument>-->
      <joint>wheel_lf_joint</joint>
      <joint>wheel_lb_joint</joint>
      <joint>wheel_rf_joint</joint>
      <joint>wheel_rb_joint</joint>
    </plugin>

    <plugin name="field_robot_diff_drive_controller" filename="libgazebo_ros_skid_steer_drive.so">
      <updateRate>50</updateRate>

      <robotNamespace>robot</robotNamespace>

      <commandTopic>cmd_vel</commandTopic>
      <odometryTopic>wheel_encoders/odom</odometryTopic>

      <publish_odom>true</publish_odom>
      <broadcastTF>false</broadcastTF>

      <robotBaseFrame>base_footprint</robotBaseFrame>
      <odometryFrame>odom</odometryFrame>


      <leftFrontJoint>wheel_lf_joint</leftFrontJoint>
      <rightFrontJoint>wheel_rf_joint</rightFrontJoint>

      <leftRearJoint>wheel_lb_joint</leftRearJoint>
      <rightRearJoint>wheel_rb_joint</rightRearJoint>


      <wheelSeparation>0.4875</wheelSeparation>
      <!-- <wheel_separation>0.475</wheel_separation>
      <wheel_separation>0.5</wheel_separation> -->

      <wheelDiameter>0.24669</wheelDiameter>

      <torque>10</torque>

    </plugin>

  </gazebo>

  <!-- CAMERA PLUGINS/SENSORS -->
  <gazebo reference="camera_front_virtual_link">
    <sensor type="camera" name="camera_front">
      <visualize>true</visualize>
      <updateRate>30</updateRate>
      <camera name="camera_front">
        <horizontal_fov>2.1</horizontal_fov>
        <image>
          <width>640</width>
          <height>480</height>
          <format>R8G8B8</format>
        </image>
        <clip>
          <near>0.02</near>
          <far>300</far>
        </clip>
        <noise>
          <type>gaussian</type>
          <mean>0.0</mean>
          <stddev>0.007</stddev>
        </noise>
        <distortion>
          <k1>0.0</k1>
          <k2>0.0</k2>
          <k3>0.0</k3>
          <p1>0.0</p1>
          <p2>0.0</p2>
          <center>0.5 0.5</center>
        </distortion>
      </camera>
      <plugin name="gazebo_cam_front_plugin" filename="libgazebo_ros_camera.so">

        <robotNamespace>robot</robotNamespace>
        <imageTopicName>image_raw</imageTopicName>
        <cameraInfoTopicName>camera_info</cameraInfoTopicName>

        <cameraName>camera_front</cameraName>
        <frameName>camera_front_link</frameName>
      </plugin>
    </sensor>
  </gazebo>

  <gazebo reference="camera_back_virtual_link">
    <sensor type="camera" name="camera_back">
      <visualize>true</visualize>
      <updateRate>30</updateRate>
      <camera name="camera_back">
        <horizontal_fov>2.1</horizontal_fov>
        <image>
          <width>640</width>
          <height>480</height>
          <format>R8G8B8</format>
        </image>
        <clip>
          <near>0.05</near>
          <far>100</far>
        </clip>
        <noise>
          <type>gaussian</type>
          <mean>0.0</mean>
          <stddev>0.007</stddev>
        </noise>
        <distortion>
          <k1>0.0</k1>
          <k2>0.0</k2>
          <k3>0.0</k3>
          <p1>0.0</p1>
          <p2>0.0</p2>
          <center>0.5 0.5</center>
        </distortion>
      </camera>
      <plugin name="gazebo_cam_back_plugin" filename="libgazebo_ros_camera.so">

        <robotNamespace>robot</robotNamespace>
        <imageTopicName>image_raw</imageTopicName>
        <cameraInfoTopicName>camera_info</cameraInfoTopicName>

        <cameraName>camera_back</cameraName>
        <frameName>camera_back_link</frameName>
      </plugin>
    </sensor>
  </gazebo>

  <gazebo reference="camera_right_virtual_link">
    <sensor type="camera" name="camera_right">
      <visualize>true</visualize>
      <updateRate>30</updateRate>
      <camera name="camera_right">
        <horizontal_fov>2.1</horizontal_fov>
        <image>
          <width>640</width>
          <height>480</height>
          <format>R8G8B8</format>
        </image>
        <clip>
          <near>0.05</near>
          <far>100</far>
        </clip>
        <noise>
          <type>gaussian</type>
          <mean>0.0</mean>
          <stddev>0.007</stddev>
        </noise>
        <distortion>
          <k1>0.0</k1>
          <k2>0.0</k2>
          <k3>0.0</k3>
          <p1>0.0</p1>
          <p2>0.0</p2>
          <center>0.5 0.5</center>
        </distortion>
      </camera>
      <plugin name="gazebo_cam_right_plugin" filename="libgazebo_ros_camera.so">

        <robotNamespace>robot</robotNamespace>
        <imageTopicName>image_raw</imageTopicName>
        <cameraInfoTopicName>camera_info</cameraInfoTopicName>

        <cameraName>camera_right</cameraName>
        <frameName>camera_right_link</frameName>
      </plugin>
    </sensor>
  </gazebo>

  <gazebo reference="camera_left_virtual_link">
    <sensor type="camera" name="camera_left">
      <visualize>true</visualize>
      <updateRate>30</updateRate>
      <camera name="camera_left">
        <horizontal_fov>2.1</horizontal_fov>
        <image>
          <width>640</width>
          <height>480</height>
          <format>R8G8B8</format>
        </image>
        <clip>
          <near>0.05</near>
          <far>100</far>
        </clip>
        <noise>
          <type>gaussian</type>
          <mean>0.0</mean>
          <stddev>0.007</stddev>
        </noise>
        <distortion>
          <k1>0.0</k1>
          <k2>0.0</k2>
          <k3>0.0</k3>
          <p1>0.0</p1>
          <p2>0.0</p2>
          <center>0.5 0.5</center>
        </distortion>
      </camera>
      <plugin name="gazebo_cam_left_plugin" filename="libgazebo_ros_camera.so">

        <robotNamespace>robot</robotNamespace>
        <imageTopicName>image_raw</imageTopicName>
        <cameraInfoTopicName>camera_info</cameraInfoTopicName>

        <cameraName>camera_left</cameraName>
        <frameName>camera_left_link</frameName>
      </plugin>
    </sensor>
  </gazebo>

  <!-- IMU -->
  <gazebo reference="imu_link">
    <sensor name="imu" type="imu">
      <visualize>true</visualize>
      <updateRate>50</updateRate>
      <visualize>false</visualize>
      <imu>
        <noise>
          <type>gaussian</type>
          <rate>
            <mean>0.0</mean>
            <stddev>2e-4</stddev>
            <bias_mean>0.0000075</bias_mean>
            <bias_stddev>0.0000008</bias_stddev>
          </rate>
          <accel>
            <mean>0.0</mean>
            <stddev>1.7e-2</stddev>
            <bias_mean>0.1</bias_mean>
            <bias_stddev>0.001</bias_stddev>
          </accel>
        </noise>
      </imu>
      <plugin name="imu" filename="libgazebo_ros_imu_sensor.so">
        <initialOrientationAsReference>false</initialOrientationAsReference>
        <frameName>imu_link</frameName>
        <topicName>imu/out</topicName>
        <robotNamespace>robot</robotNamespace>
      </plugin>
    </sensor>
  </gazebo>

  <!--<gazebo>
    <plugin name="gaezbo_ros_p3d" filename="libgazebo_ros_p3d.so">
      <ros>
        <namespace>robot</namespace>
        <argument>odom:=odom</argument>
      </ros>

      <frame_name>world</frame_name>
      <body_name>base_footprint</body_name>
      <updateRate>30</updateRate>
    </plugin>
  </gazebo>-->

</robot>